<?xml version="1.0"?>
<robot name="mecanum37" xmlns:xacro="http://ros.org/wiki/xacro">

  <xacro:macro name="cylinder_inertial" params="mass radius length">
	<mass value="${mass}"/>
	<inertia ixx="${((radius*radius)/4 + (length*length)/12)*mass}" ixy="0" ixz="0"
			 iyy="${((radius*radius)/4 + (length*length)/12)*mass}" iyz="0"
			 izz="${(mass*radius*radius)/2}" />
  </xacro:macro>

  <xacro:macro name="wheel_shaft" params="prefix parent_link joint_xyz joint_rpy">
    <link name="${prefix}_shaft">
      <visual><geometry>
        <cylinder radius="0.005" length="0.024" />
      </geometry><material name="black"/></visual>
      <collision><geometry>
        <cylinder radius="0.005" length="0.024" />
      </geometry></collision>
      <inertial><xacro:cylinder_inertial mass="0.01" radius="0.009" length="0.024" /></inertial>
    </link>
    <joint name="${prefix}_shaft_joint" type="fixed">
      <parent link="${parent_link}" />
      <child  link="${prefix}_shaft" />
      <origin xyz="${joint_xyz}" rpy="${joint_rpy}" />
      <dynamics damping="0.001" friction="0.0" />
    </joint>
  </xacro:macro>

  <xacro:macro name="wheel_frame" params="prefix inout to_shaft_length">
    <link name="${prefix}_${inout}_frame">
      <visual><geometry>
        <cylinder radius="0.017" length="0.005" />
      </geometry><material name="black"/></visual>
    </link>
    <joint name="${prefix}_${inout}_frame" type="fixed">
      <parent link="${prefix}_shaft" />
      <child  link="${prefix}_${inout}_frame" />
      <origin xyz="0 0 ${to_shaft_length}" rpy="0 0 0" />
    </joint>
    <gazebo reference="${prefix}_${inout}_frame">
      <material>Gazebo/Black</material>
    </gazebo>
  </xacro:macro>

  <xacro:macro name="barrel" params="prefix num dir rot">
    <link name="${prefix}_barrel${num}_link">
      <visual><geometry>
          <mesh filename="package://omniduino_description/meshes/ffbarrel.stl" />
      </geometry></visual>
      <collision><geometry>
          <mesh filename="package://omniduino_description/meshes/ffbarrel.stl" />
      </geometry></collision>
      <inertial><xacro:cylinder_inertial mass="0.01225" radius="0.00956" length="0.0381" /></inertial>
    </link>
    <joint name="${prefix}_barrel${num}_joint" type="continuous">
      <parent link="${prefix}_shaft"/>
      <child link="${prefix}_barrel${num}_link"/>
      <origin rpy="0 ${pi/4*rot} ${radians(dir)+pi/2}" xyz="${0.012975*cos(radians(dir))} ${0.012975*sin(radians(dir))} 0"/>
      <axis xyz="1 0 0"/>
      <dynamics damping="0.001"  friction="0.0"/>
    </joint>
    <gazebo reference="${prefix}_barrel${num}_link">
      <material>Gazebo/Green</material>
      <mu1 value="2.5" />
      <mu2 value="2.5" />
      <kp value="50000" />
      <kd value="100" />
    </gazebo>
  </xacro:macro>

  <xacro:macro name="barrels" params="prefix rot" >
    <xacro:barrel prefix="${prefix}"  num="0" dir="0"   rot="${rot}" />
    <xacro:barrel prefix="${prefix}"  num="1" dir="60"  rot="${rot}" />
    <xacro:barrel prefix="${prefix}"  num="2" dir="120" rot="${rot}" />
    <xacro:barrel prefix="${prefix}"  num="3" dir="180" rot="${rot}" />
    <xacro:barrel prefix="${prefix}"  num="4" dir="240" rot="${rot}" />
    <xacro:barrel prefix="${prefix}"  num="5" dir="300" rot="${rot}" />
  </xacro:macro>

  <xacro:macro name="mecanum_wheel" params="prefix parent_link rot joint_xyz joint_rpy">
    <xacro:wheel_shaft prefix="${prefix}" parent_link="${parent_link}" joint_xyz="${joint_xyz}" joint_rpy="${joint_rpy}"/>
    <xacro:wheel_frame prefix="${prefix}" inout="inside"  to_shaft_length=" 0.0135" />
    <xacro:wheel_frame prefix="${prefix}" inout="outside" to_shaft_length="-0.0135" />
    <xacro:barrels prefix="${prefix}" rot="${rot}" />
  </xacro:macro>
  
</robot>
